# バックエンドの実装 その2
前回は、簡易的な HTTP サーバの実装を行いました。
前回の実装方法では、主にテストを行う際にいくつか問題があります。

- テスト完了後に終了する術がない
- 出力を検出しづらい
- 異常時に ```os.Exit``` 関数が呼ばれてしまう
- ポート番号が固定されているため、テストで起動に失敗する可能性がある

そこで、今回はサーバの起動関連の処理を ```run``` 関数に委譲し、テストを書いてみます。

## golang.org/x/sync パッケージの導入
今の実装では HTTP サーバの終了を通知する手段がありません。
そこで、準標準パッケージである ```golang.org/x/sync``` を導入します。

```bash
$ go get -u golang.org/x/sync
```

このパッケージに含まれる ```errgroup``` サブパッケージの ```errgroup.Group``` 型を使うことで、戻り値にエラーが含まれるゴルーチン間の並行処理が簡単に実装できるようになるそうです。

## ```run``` 関数の実装
```run``` 関数では、```*errgroup.Group``` 型の ```Go``` メソッドで ```func() error``` のシグネチャを持つ関数を別ゴルーチンで起動し、その中で ```*http.Server.ListenAndServe``` メソッドを実行してリクエストを待機します。
サーバの動作を停止する場合には、以下の流れで処理が行われ、```mmain``` 関数にエラーを返します。

1. ```<-ctx.Done()``` の戻り値として得られるチャネルから終了の通知を待つ
2. ```*http.Server.Shutdown``` メソッドが実行される
3. 別ゴルーチンで実行していた ```*http.Server.ListenAndServe``` が終了する
4. 別ゴルーチンで実行していた無名関数 (```func() error```) が終了する
5. ```*errgroup.Group.Wait``` メソッドが終了する
6. 無名関数 (```func() error```) の戻り値を ```main``` 関数に返して ```run``` 関数を終了

上記の実装は以下のようになります。

```go
func main() {
	if err := run(context.Background()); err != nil {
		fmt.Printf("failed to terminate server: %v", err)
	}
}

func run(ctx context.Context) error {
	s := &http.Server{
		Addr: ":8000",
		Handler: http.HandlerFunc(func(w http.ResponseWriter, r *http.Request) {
			fmt.Fprintf(w, "Hello, %s!\n", r.URL.Path[1:])
		}),
	}

	eg, ctx := errgroup.WithContext(ctx)

	// eg.Go メソッドで HTTP サーバを起動するゴルーチンを立ち上げる
	eg.Go(func() error {
		// http.ErrServerClosed は http.Server.Shutdown() が正常終了したことを示すエラー
		if err := s.ListenAndServe(); err != nil && err != http.ErrServerClosed {
			log.Printf("failed to close: %+v", err)
			return err
		}
		return nil
	})

	// チャネルからの終了通知を待機
	<-ctx.Done()
	if err := s.Shutdown(context.Background()); err != nil {
		log.Printf("failed to shutdown: %+v", err)
	}

	// Go メソッドで起動したゴルーチンの終了を待つ
	return eg.Wait()
}
```

## ```run``` 関数のテスト
```main``` 関数から HTTP サーバの起動・終了の処理を ```run``` 関数に切り出せたので、

- 期待通りに HTTP サーバが起動しているか
- テストコードから意図通りに終了できるか

の2点を確認するテストを書いてみます。
テストは次のような流れで記述します。

1. キャンセル可能な ```context.Context``` のオブジェクトを作成する
2. 別ゴルーチンでテスト対象の ```run``` 関数を実行して HTTP サーバを起動する
3. エンドポイントに GET リクエストを送信する
4. ```cancel``` 関数を実行する
5. ```*errgroup.Group.Wait``` メソッド経由腕 ```run``` 関数の戻り値を検証する
6. GET リクエストで得られたレスポンスのボディが、期待した文字列であることを検証する

```backend/main_test.go```
```go
func TestRun(t *testing.T) {
	ctx, cancel := context.WithCancel(context.Background())
	eg, ctx := errgroup.WithContext(ctx)
	eg.Go(func() error {
		return run(ctx)
	})

	in := "message"
	rsp, err := http.Get("http://localhost:8000/" + in)
	if err != nil {
		t.Errorf("faild to get: %+v", err)
	}
	defer rsp.Body.Close()
	got, err := io.ReadAll(rsp.Body)
	if err != nil {
		t.Fatalf("failed to read body: %+v", err)
	}

	// HTTP サーバからのレスポンスを検証
	want := fmt.Sprintf("Hello, %s!", in)
	if string(got) != want {
		t.Errorf("wannt %q, but got %q", want, got)
	}

	// run 関数に終了通知を送信
	cancel()

	// run 関数の戻り値を検証する
	if err := eg.Wait(); err != nil {
		t.Fatal(err)
	}
}
```

いったん Air の実行を停止してから、以下のコマンドでテストが通ることを確認します。

```bash
$ go test -v ./...
=== RUN   TestRun
--- PASS: TestRun (0.00s)
PASS
ok      github.com/iinuma0710/react-go-blog/backend     (cached)
```

今回は Air を止めてからテストを実行しましたが、止めずにテストを実行すると「指定のポートがもう使われているよ」という旨のエラーメッセージが出て、テストが fail します。
このエラーは ```go run``` を実行している最中にも発生し、テストのためにいちいちコマンドでサーバの動作を止める必要があるため、次回は外部から動的にポート番号を設定する方法を見ていきます。